Workbook
Name _31_May_99: "Fin_de_ periodo"
Name Amargura: #REF!
Name Amargura: #REF!
Name Amargura: #REF!
Name ANUAL: #REF!
Name ANUAL: #REF!
Name ANUAL_01: #REF!
Name ANUAL_01: #REF!
Name anual01: #REF!
Name anual01: #REF!
Name area: #REF!
Name Avance: #REF!
Name Avance: #REF!
Name Avance: #REF!
Name Cantidad01: #REF!
Name Cantidad01: #REF!
Name Cantidad01: #REF!
Name Cantidad02: #REF!
Name Cantidad02: #REF!
Name Cantidad02: #REF!
Name Cantidad03: #REF!
Name Cantidad03: #REF!
Name Cantidad03: #REF!
Name Cantidad04: #REF!
Name Cantidad04: #REF!
Name Cantidad04: #REF!
Name Cantidad05: #REF!
Name Cantidad05: #REF!
Name Cantidad05: #REF!
Name Cantidad06: #REF!
Name Cantidad06: #REF!
Name Cantidad06: #REF!
Name Cantidad12: #REF!
Name Cantidad12: #REF!
Name Cantidad12: #REF!
Name Cantidad31: #REF!
Name Cantidad31: #REF!
Name Cantidad31: #REF!
Name cargo: #REF!
Name cargocontacto: #REF!
Name cargoresponsabledelaobra: #REF!
Name cargovendedor: #REF!
Name Catalogo: #REF!
Name ciudad: #REF!
Name ciudadcliente: #REF!
Name ciudaddelaobra: #REF!
Name cmic: #REF!
Name codigodelaobra: #REF!
Name codigopostalcliente: #REF!
Name codigopostaldelaobra: #REF!
Name codigovendedor: #REF!
Name colonia: #REF!
Name coloniacliente: #REF!
Name coloniadelaobra: #REF!
Name Con_Sanción: #REF!
Name Con_Sanción: #REF!
Name Con_Sanción: #REF!
Name contactocliente: #REF!
Name copia: #REF!
Name copia: #REF!

Sheet EST. 1
A1: 0 | B1: 0 | C1: 0 | D1: 0 | E1: 0 | F1: 0 | G1: 0 | H1: 0 | I1: 0 | J1: 0 | K1: 0 | L1: 0 | N1: 0 | O1: 0 | P1: 0 | Q1: 0 | R1: 0 | W1: 0 | X1: 0 | Y1: 0 | Z1: 0 | AA1: 0 | AB1: 0 | AC1: 0
A2: 0 | B2: 0 | C2: 0 | D2: 0 | F2: PUNTA CUERNA RESIDENCIAL | AC2: 0
A3: 0 | O3: FECHA | Q3: ESTIMACION N° | R3: 0 | AC3: 0
A4: 0 | B4: 0 | C4: 0 | D4: 0 | F4: OBRA: | G4: PUNTA CUERNA RESIDENCIAL | K4: ESTIMACION DE OBRA | O4: 46235 | Q4: 1 | AC4: 0
A5: 0 | AC5: 0
A6: 0 | E6: 0 | F6: 0 | G6: 0 | H6: 0 | I6: 0 | O6: 0 | P6: 0 | Q6: 0 | R6: 0 | W6: 0 | X6: 0 | Y6: 0 | Z6: 0 | AA6: 0 | AB6: 0 | AC6: 0
A7: 0 | B7: 0 | C7: 0 | D7: 0 | E7: 0 | F7: 0 | G7: 0 | H7: 0 | I7: 0 | J7: 0 | K7: 0 | L7: 0 | N7: 0 | O7: 0 | P7: 0 | Q7: 0 | R7: 0 | W7: 0 | X7: 0 | Y7: 0 | Z7: 0 | AA7: 0 | AB7: 0 | AC7: 0
A8: 0 | B8: DATOS DEL CONTRATISTA | C8: 0 | D8: 0 | E8: DATOS DEL CONTRATO | J8: INFORMACION GENERAL | K8: 0 | L8: 0 | N8: 0 | O8: 0 | P8: 0 | Q8: 0 | R8: 0 | W8: 0 | X8: 0 | Y8: 0 | Z8: 0 | AA8: 0 | AB8: 0 | AC8: 0
A9: 0 | B9: NOMBRE: | C9: GRUPO ROFORB S DE RL DE CV | E9: FECHA DE INICIO | J9: 0 | K9: 0 | L9: S/ IVA | M9: C/IVA | O9: ANTICIPO OTORGADO | Q9: =+L10*0 -> 0 | W9: 0 | X9: 0 | Y9: 0 | Z9: 0 | AA9: 0 | AB9: 0 | AC9: 0
A10: 0 | B10: REG.FED DE CAUSANTES: | D10: GRO2312152M8 | E10: MES | F10: DIA | G10: AÑO | H10: PRORROGA | I10: FECHA TERMINACION | J10: IMPORTE TOTAL CONTRATO | K10: 0 | L10: =I53 -> 44127.789 | M10: =L10*1.16 -> 51188.235 | O10: AMORTIZACION HASTA | W10: 0 | X10: 0 | Y10: 0 | Z10: 0 | AA10: 0 | AB10: 0 | AC10: 0
A11: 0 | B11: N° REGISTRO I.M.S.S. | D11: D1566242106 | E11: 07 | F11: 23 | G11: 2026 | J11: ESTIMADO A LA FECHA | K11: 0 | L11: =M53+K53 -> 62159.91 | M11: =L11*1.16 -> 72105.496 | O11: ESTIMACION ANTERIOR | Q11: =+Q9 -> 0 | W11: 0 | X11: 0 | Y11: 0 | Z11: 0 | AA11: 0 | AB11: 0 | AC11: 0
A12: 0 | E12: FECHA DE TERMINACION | J12: ADITIVAS/DEDUCTIVAS A LA FECHA | K12: 0 | L12: 0 | M12: =L12*1.16 -> 0 | O12: AMORTIZACION EN ESTA | W12: 0 | X12: 0 | Y12: 0 | Z12: 0 | AA12: 0 | AB12: 0 | AC12: 0
A13: 0 | B13: UBICACIÓN | E13: MES | F13: DIA | G13: AÑO | H13: PERIODO ESTIMACION | I13: 0 | J13: IMPORTE CONTRACTUAL MODIFICADO | L13: =I53 -> 44127.789 | M13: =L13*1.16 -> 51188.235 | O13: ESTIMACION | W13: 0 | X13: 0 | Y13: 0 | Z13: 0 | AA13: 0 | AB13: 0 | AC13: 0
A14: 0 | B14: PROGRAMA : | C14: URBANIZACION | E14: 08 | F14: 01 | G14: 2026 | H14: DEL | I14: AL | J14: IMPORTE POR ESTIMAR | L14: =+L10-L11+L12 -> -18032.121 | M14: =+M10-M11+M12 -> -20917.261 | O14: TOTAL AMORTIZADO | Q14: =+Q11+Q12 -> 0 | W14: 0 | X14: 0 | Y14: 0 | Z14: 0 | AA14: 0 | AB14: 0 | AC14: 0
A15: 0 | B15: TRABAJO : | C15: URBANIZACION DISEÑO DE PRIVADA EN CASAS MODELO | E15: NUMERO DE CONTRATO | H15: 46230 | I15: =H15+5 -> 46235 | J15: 0 | K15: 0 | L15: 0 | M15: 0 | O15: POR AMORTIZAR | Q15: =+Q9-Q14 -> 0 | W15: 0 | X15: 0 | Y15: 0 | Z15: 0 | AA15: 0 | AB15: 0 | AC15: 0
A16: 0 | E16: 1 CONV-1 OE | I16: 0 | J16: 0 | K16: 0 | L16: 0 | N16: 0 | O16: 0 | P16: 0 | Q16: 0 | R16: 0 | W16: 0 | X16: 0 | Y16: 0 | Z16: 0 | AA16: 0 | AB16: 0 | AC16: 0
A17: 0 | B17: C.C. | C17: P31 | H17: 0 | I17: 0 | J17: 0 | K17: 0 | L17: 0 | N17: 0 | O17: 0 | P17: 0 | Q17: 0 | R17: 0 | W17: 0 | X17: 0 | Y17: 0 | Z17: 0 | AA17: 0 | AB17: 0 | AC17: 0
A18: 0 | B18: 0 | C18: 0 | D18: 0 | E18: 0 | F18: 0 | G18: PRESUPUESTO | H18: 0 | I18: 0 | J18: HASTA ESTIMACION ANTERIOR | K18: 0 | L18: ESTA ESTIMACION | N18: 0 | O18: ESTIMADO A LA FECHA | P18: 0 | Q18: POR EJECUTAR | R18: 0 | W18: 0 | X18: 0 | Y18: 0 | Z18: 0 | AA18: 0 | AB18: 0 | AC18: 0
A19: 0 | B19: CLAVE | C19: CONCEPTO | D19: 0 | E19: 0 | F19: 0 | G19: VOLUMEN | H19: P.U. | I19: IMPORTE | J19: VOLUMEN | K19: IMPORTE | L19: Vol | M19: IMPORTE | O19: VOLUMEN | P19: IMPORTE | Q19: VOLUMEN | R19: IMPORTE | AA19: 0 | AB19: 0 | AC19: 0
B20: 5 | C20: CASAS MUESTRA
B21: 10 | C21: ESTACIONAMIENTO
B22: 4020938 | C22: SUM Y COL ADOCRETO RECTANGULAR 20 X 10 CM | G22: 28.937 | H22: 200.65 | I22: =G22*H22 -> 5806.2091 | K22: =H22*J22 -> 0 | L22: ='CROQUIS EST1'!K23 -> 35.2 | M22: =H22*L22 -> 7062.88 | O22: =J22+L22 -> 35.2 | P22: =H22*O22 -> 7062.88 | Q22: =G22-O22 -> -6.263 | R22: =I22-P22 -> -1256.671
B23: 4020766 | C23: SUM Y COL DE ARENA | G23: 2.3535 | H23: 176.1 | I23: =G23*H23 -> 414.45135 | K23: =H23*J23 -> 0 | M23: =H23*L23 -> 0 | O23: =J23+L23 -> 0 | P23: =H23*O23 -> 0 | Q23: =G23-O23 -> 2.3535 | R23: =I23-P23 -> 414.45135
B24: 4020859 | C24: SUMINISTRO DE MATERIAL CEMENTANTE | G24: 46.78299 | H24: 379.3 | I24: =G24*H24 -> 17744.788 | K24: =H24*J24 -> 0 | L24: ='CROQUIS EST1'!K65 -> 53.5 | M24: =H24*L24 -> 20292.55 | O24: =J24+L24 -> 53.5 | P24: =H24*O24 -> 20292.55 | Q24: =G24-O24 -> -6.71701 | R24: =I24-P24 -> -2547.7619
A26: 0 | B26: 8 | C26: DISEÑO DE PRIVADA | AA26: 0 | AB26: 0 | AC26: 0
A27: 0 | B27: 4020260 | C27: HUELLA CONCRETO 60X50 CM | G27: 9 | H27: 722.18 | I27: =G27*H27 -> 6499.62 | K27: =H27*J27 -> 0 | L27: 9 | M27: =H27*L27 -> 6499.62 | O27: =J27+L27 -> 9 | P27: =H27*O27 -> 6499.62 | Q27: =G27-O27 -> 0 | R27: =I27-P27 -> 0 | AA27: 0 | AB27: 0 | AC27: 0
A29: 0 | B29: 9 | C29: GUARNICIONES Y BANQUETAS | AA29: 0 | AB29: 0 | AC29: 0
B30: 4020834 | C30: BANQUETA DE 10CM ESPESOR DE CONCRETO HCO F | G30: 25.6 | H30: 533.7 | I30: =G30*H30 -> 13662.72 | K30: =H30*J30 -> 0 | L30: ='CROQUIS EST1'!K152 -> 39 | M30: =H30*L30 -> 20814.3 | O30: =J30+L30 -> 39 | P30: =H30*O30 -> 20814.3 | Q30: =G30-O30 -> -13.4 | R30: =I30-P30 -> -7151.58
A31: 0 | B31: 0 | C31: CONST GUARNICION TIPO CONCRETO HCO, F'C=150 | G31: 0 | H31: 212.8 | I31: =G31*H31 -> 0 | K31: =H31*J31 -> 0 | L31: ='CROQUIS EST1'!K194 -> 35.2 | M31: =H31*L31 -> 7490.56 | O31: =J31+L31 -> 35.2 | P31: =H31*O31 -> 7490.56 | Q31: =G31-O31 -> -35.2 | R31: =I31-P31 -> -7490.56 | AA31: 0 | AB31: 0 | AC31: 0
A35: 0 | W35: 0 | X35: 0 | Y35: 0 | Z35: 0 | AA35: 0 | AB35: 0 | AC35: 0
A36: 0 | W36: 0 | X36: 0 | Y36: 0 | Z36: 0 | AA36: 0 | AB36: 0 | AC36: 0
C53: TOTAL PRESUPUESTO | I53: =SUM(I22:I52) -> 44127.789 | K53: =SUM(K22:K52) -> 0 | M53: =SUM(M22:N52) -> 62159.91 | P53: =SUM(P22:P52) -> 62159.91 | R53: =SUM(R22:R52) -> -18032.121
K55: SUBTOTAL | M55: =M53 -> 62159.91
B56: OBSERVACIONES: | K56: MENOS AMORTIZACION ANTICIPO | M56: =+Q12 -> 0 | O56: FONDO DE GARANTIA RETENIDO: | R56: =K53*0.06 -> 0
K57: SUBTOTAL | M57: =M55-M56 -> 62159.91 | O57: F.G. RETENIDO ESTA ESTIMACION: | R57: =M60 -> 3729.5946
K58: I.V.A 16% | M58: =M57*0.16 -> 9945.5856 | O58: TOTAL RETENIDO A LA FECHA: | R58: =SUM(R56:R57) -> 3729.5946
K59: TOTAL | M59: =SUM(M57:N58) -> 72105.496
K60: MENOS FONDO DE GARANTIA ( 6% ) | M60: =+M55*0.06 -> 3729.5946
K61: NETO A PAGAR | M61: =M57+M58-M60 -> 68375.901
B62: FORMULO | E62: ELABORO | L62: AUTORIZO | P62: APROBO
...

Sheet CROQUIS EST1
E5: ='EST. 1'!F2 -> PUNTA CUERNA RESIDENCIAL
M9: ESTIMACION No.: | N9: FECHA: | O9: ='EST. 1'!Q4 -> 1
A10: PROGRAMA: | B10: ='EST. 1'!C14 -> URBANIZACION | G10: FECHA: | H10: ='EST. 1'!O4 -> 46235
A11: TRABAJO: | B11: ='EST. 1'!C15 -> URBANIZACION DISEÑO DE PRIVADA EN CASAS MODELO | G11: PERÍODO: | H11: ='EST. 1'!H15 -> 46230 | I11: AL | J11: ='EST. 1'!I15 -> 46235 | L11: CROQUIS
A12: CONTRATISTA: | B12: ='EST. 1'!C9 -> GRUPO ROFORB S DE RL DE CV
A14: CLAVE | B14: PARTIDA | C14: CLAVE | D14: SUBPARTIDA | J14: ACTIVIDADES
A15: ='EST. 1'!B20 -> 5 | B15: ='EST. 1'!C20 -> CASAS MUESTRA | C15: ='EST. 1'!B21 -> 10 | D15: ='EST. 1'!C21 -> ESTACIONAMIENTO
A16: CLAVE | B16: DESCRIPCION | C16: TRAMO | D16: UNIDAD | E16: LARGO | F16: ANCHO | G16: ALTO | I16: PZAS | J16: SUBTOTAL | K16: TOTAL
A17: ='EST. 1'!B22 -> 4020938 | B17: ='EST. 1'!C22 -> SUM Y COL ADOCRETO RECTANGULAR 20 X 10 CM
B18: CASAS MUESTRA | C18: AREA 1 | D18: M2 | E18: 4.4 | F18: 0.5 | I18: 2 | J18: =TRUNC(E18*F18*I18,2) -> 4.4
B19: CASAS MUESTRA | C19: AREA 2 | D19: M2 | E19: 4.4 | F19: 0.6 | I19: 6 | J19: =TRUNC(E19*F19*I19,2) -> 15.84
B20: CASAS MUESTRA | C20: AREA 3 | D20: M2 | E20: 4.4 | F20: 0.9 | I20: 2 | J20: =TRUNC(E20*F20*I20,2) -> 7.92
B21: CASAS MUESTRA | C21: AREA 4 | D21: M2 | E21: 4.4 | F21: 0.8 | I21: 2 | J21: =TRUNC(E21*F21*I21,2) -> 7.04
B23: TOTAL | D23: M2 | K23: =SUM(J18:J22) -> 35.2
A57: CONTRATISTA | E57: JEFE DE URBANIZACIÓN | N57: GERENTE TECNICO
A58: GRUPO ROFORB S DE RL DE CV | E58: ARQ. VERÓNICA ITZEL GARCIA SILVA | N58: ING. ANDRES GONZALEZ RODRIGUEZ
A60: CLAVE | B60: PARTIDA | C60: CLAVE | D60: SUBPARTIDA | J60: ACTIVIDADES
A61: =A15 -> 5 | B61: =B15 -> CASAS MUESTRA | C61: =C15 -> 10 | D61: =D15 -> ESTACIONAMIENTO
A62: CLAVE | B62: DESCRIPCION | C62: TRAMO | D62: UNIDAD | E62: LARGO | F62: ANCHO | G62: ALTO | I62: PZAS | J62: SUBTOTAL | K62: TOTAL
A63: ='EST. 1'!B24 -> 4020859 | B63: ='EST. 1'!C24 -> SUMINISTRO DE MATERIAL CEMENTANTE
B64: CASAS MUESTRA | C64: FIGURA 1 | D64: M2 | E64: 4.4 | F64: 1.52 | I64: 8 | J64: =TRUNC(E64*F64*I64,2) -> 53.5
B65: TOTAL | D65: ML | K65: =SUM(J64:J64) -> 53.5
A99: CONTRATISTA | E99: JEFE DE URBANIZACIÓN | N99: GERENTE TECNICO
A100: GRUPO ROFORB S DE RL DE CV | E100: ARQ. VERÓNICA ITZEL GARCIA SILVA | N100: ING. ANDRES GONZALEZ RODRIGUEZ
A101: CLAVE | B101: PARTIDA | C101: CLAVE | D101: SUBPARTIDA | J101: ACTIVIDADES
A102: ='EST. 1'!B20 -> 5 | B102: ='EST. 1'!C20 -> CASAS MUESTRA | C102: ='EST. 1'!B26 -> 8 | D102: ='EST. 1'!C26 -> DISEÑO DE PRIVADA
A103: CLAVE | B103: DESCRIPCION | C103: TRAMO | D103: UNIDAD | E103: LARGO | F103: ANCHO | G103: ALTO | I103: PZAS | J103: SUBTOTAL | K103: TOTAL
A104: ='EST. 1'!B27 -> 4020260 | B104: ='EST. 1'!C27 -> HUELLA CONCRETO 60X50 CM
B105: CONSTRUC HUELLAS DE 90X60 CM | D105: PZA | I105: 6 | K105: =I105 -> 6
H136: NOTA: SE REALIZARON HUELLAS DE CONCRETO DE 90X60 CM
A146: CONTRATISTA | E146: JEFE DE URBANIZACIÓN | N146: GERENTE TECNICO
A147: GRUPO ROFORB S DE RL DE CV | E147: ARQ. VERÓNICA ITZEL GARCIA SILVA | N147: ING. ANDRES GONZALEZ RODRIGUEZ
A148: CLAVE | B148: PARTIDA | C148: CLAVE | D148: SUBPARTIDA | J148: ACTIVIDADES
A149: ='EST. 1'!B20 -> 5 | B149: ='EST. 1'!C20 -> CASAS MUESTRA | C149: ='EST. 1'!B29 -> 9 | D149: ='EST. 1'!C29 -> GUARNICIONES Y BANQUETAS
A150: CLAVE | B150: DESCRIPCION | C150: TRAMO | D150: UNIDAD | E150: LARGO | F150: ANCHO | G150: ALTO | I150: PZAS | J150: SUBTOTAL | K150: TOTAL
A151: ='EST. 1'!B30 -> 4020834 | B151: ='EST. 1'!C30 -> BANQUETA DE 10CM ESPESOR DE CONCRETO HCO F
B152: LADO NORTE | D152: M2 | E152: 30 | F152: 1.3 | I152: 1 | K152: =TRUNC(E152*F152*I152,2) -> 39
A188: CONTRATISTA | E188: JEFE DE URBANIZACIÓN | N188: GERENTE TECNICO
A189: GRUPO ROFORB S DE RL DE CV | E189: ARQ. VERÓNICA ITZEL GARCIA SILVA | N189: ING. ANDRES GONZALEZ RODRIGUEZ
A190: CLAVE | B190: PARTIDA | C190: CLAVE | D190: SUBPARTIDA | J190: ACTIVIDADES
...

Sheet REP. FOT. EST1
E5: ='EST. 1'!F2 -> PUNTA CUERNA RESIDENCIAL
M9: ESTIMACION No.: | N9: FECHA: | O9: ='EST. 1'!Q4 -> 1
A10: PROGRAMA: | B10: ='EST. 1'!C14 -> URBANIZACION | G10: FECHA: | H10: ='EST. 1'!O4 -> 46235
A11: TRABAJO: | B11: ='EST. 1'!C15 -> URBANIZACION DISEÑO DE PRIVADA EN CASAS MODELO | G11: PERÍODO: | H11: ='EST. 1'!H15 -> 46230 | I11: AL | J11: ='EST. 1'!I15 -> 46235 | L11: REPORTE FOTOGRAFICO
A12: CONTRATISTA: | B12: ='EST. 1'!C9 -> GRUPO ROFORB S DE RL DE CV
A14: CLAVE | B14: PARTIDA | C14: CLAVE | D14: SUBPARTIDA | J14: ACTIVIDADES
A15: ='EST. 1'!B20 -> 5 | B15: ='EST. 1'!C20 -> CASAS MUESTRA | C15: ='EST. 1'!B21 -> 10 | D15: ='EST. 1'!C21 -> ESTACIONAMIENTO | E15: =#REF! -> #REF! | F15: =#REF! -> #REF! | G15: =#REF! -> #REF! | H15: =#REF! -> #REF! | I15: =#REF! -> #REF!
A56: CONTRATISTA | E56: JEFE DE URBANIZACIÓN | N56: GERENTE TECNICO
A57: GRUPO ROFORB S DE RL DE CV | E57: ARQ. VERÓNICA ITZEL GARCIA SILVA | N57: ING. ANDRES GONZALEZ RODRIGUEZ
A59: CLAVE | B59: PARTIDA | C59: CLAVE | D59: SUBPARTIDA | J59: ACTIVIDADES
A60: =A15 -> 5 | B60: =B15 -> CASAS MUESTRA | C60: =C15 -> 10 | D60: =D15 -> ESTACIONAMIENTO
A101: CONTRATISTA | E101: JEFE DE URBANIZACIÓN | N101: GERENTE TECNICO
A102: GRUPO ROFORB S DE RL DE CV | E102: ARQ. VERÓNICA ITZEL GARCIA SILVA | N102: ING. ANDRES GONZALEZ RODRIGUEZ
A103: CLAVE | B103: PARTIDA | C103: CLAVE | D103: SUBPARTIDA | J103: ACTIVIDADES
A104: ='EST. 1'!B20 -> 5 | B104: ='EST. 1'!C20 -> CASAS MUESTRA | C104: ='EST. 1'!B21 -> 10 | D104: ='EST. 1'!C21 -> ESTACIONAMIENTO
A151: CONTRATISTA | E151: JEFE DE URBANIZACIÓN | N151: GERENTE TECNICO
A152: GRUPO ROFORB S DE RL DE CV | E152: ARQ. VERÓNICA ITZEL GARCIA SILVA | N152: ING. ANDRES GONZALEZ RODRIGUEZ
